<robot
  name="simple_rover">
  <link name="base_link" />
  <joint name="base_link_to_body_link" type="fixed">
    <parent link="base_link"/>
    <child link="body_link"/>
  </joint>
  <link
    name="body_link">
    <inertial>
      <origin
        xyz="0.0 0.0 2"
        rpy="0 0 0" />
      <mass
        value="0.1" />
      <inertia
        ixx="0.110219194515471"
        ixy="0.0184184696712983"
        ixz="5.50641462037452E-16"
        iyy="0.232127501030259"
        iyz="3.13065611806685E-15"
        izz="0.164776567925145" />
    </inertial>
    <visual>
      <origin
        xyz="0 0 0"
        rpy="0 0 0" />
      <geometry>
        <box size = ".515 .448 .2" />
      </geometry>
    </visual>
    <collision>
      <origin
        xyz="0 0 0"
        rpy="0 0 0" />
      <geometry>
        <box size = ".515 .448 .2" />
      </geometry>
    </collision>
  </link>

  <link
    name="left_rocker_link">
    <inertial>
      <origin
        xyz="-0.234329240297601 -0.137001497213899 0.00317500000000011"
        rpy="0 0 0" />
      <mass
        value="0.249259082823854" />
      <inertia
        ixx="0"
        ixy="0"
        ixz="0"
        iyy="0"
        iyz="0"
        izz="0" />
    </inertial>
    <visual>
      <origin
        xyz=".376475 0 0"
        rpy="0 0 0" />
      <geometry>
        <box size = ".780 .00635 .05876" />
      </geometry>
    </visual>
    <collision>
      <origin
        xyz=".376475 0 0"
        rpy="0 0 0" />
      <geometry>
        <box size = ".780 .00635 .05876" />
      </geometry>
    </collision>
    <visual>
      <origin
        xyz="-0.01581739 0 -0.12489"
        rpy="0 -1.69677 0" />
      <geometry>
        <box size = ".280 .00635 .05876" />
      </geometry>
    </visual>
    <collision>
      <origin
        xyz="-0.01581739 0 -0.12489"
        rpy="0 -1.69677 0" />
      <geometry>
        <box size = ".280 .00635 .05876" />
      </geometry>
    </collision>
  </link>

  <joint
    name="left_rocker_joint"
    type="revolute">
    <origin
      xyz="0.06861 -0.276585 -0.06254"
      rpy="0 0.5236 0" />
    <parent
      link="body_link" />
    <child
      link="left_rocker_link" />
    <axis
      xyz="0 1 0" />
    <limit
      lower="-1.0472"
      upper="1.0472"
      effort="0"
      velocity="0" />
  </joint>

  <link
    name="right_rocker_link">
    <inertial>
      <origin
        xyz="-0.234329240297601 -0.137001497213899 0.00317500000000011"
        rpy="0 0 0" />
      <mass
        value="0.249259082823854" />
      <inertia
        ixx="0"
        ixy="0"
        ixz="0"
        iyy="0"
        iyz="0"
        izz="0" />
    </inertial>
    <visual>
      <origin
        xyz=".376475 0 0"
        rpy="0 0 0" />
      <geometry>
        <box size = ".780 .00635 .05876" />
      </geometry>
    </visual>
    <collision>
      <origin
        xyz=".376475 0 0"
        rpy="0 0 0" />
      <geometry>
        <box size = ".780 .00635 .05876" />
      </geometry>
    </collision>
    <visual>
      <origin
        xyz="-0.01581739 0 -0.12489"
        rpy="0 -1.69677 0" />
      <geometry>
        <box size = ".280 .00635 .05876" />
      </geometry>
    </visual>
    <collision>
      <origin
        xyz="-0.01581739 0 -0.12489"
        rpy="0 -1.69677 0" />
      <geometry>
        <box size = ".280 .00635 .05876" />
      </geometry>
    </collision>
  </link>

  <joint
    name="right_rocker_joint"
    type="revolute">
    <origin
      xyz="0.06861 0.276585 -0.06254"
      rpy="0 0.5236 0" />
    <parent
      link="base_link" />
    <child
      link="right_rocker_link" />
    <axis
      xyz="0 1 0" />
    <limit
      lower="-1.0472"
      upper="1.0472"
      effort="0"
      velocity="0" />
  </joint>

  <link
    name="left_front_wheel_link">
    <inertial>
      <origin
        xyz="0 0 0"
        rpy="0 0 0" />
      <mass
        value="5.28366197630003" />
      <inertia
        ixx="0"
        ixy="0"
        ixz="0"
        iyy="0"
        iyz="0"
        izz="0" />
    </inertial>
    <visual>
      <origin
        xyz="0 0 0"
        rpy="1.5708 0 0" />
      <geometry>
        <cylinder length=".1366" radius=".14879"/>
      </geometry>
    </visual>
    <collision>
      <origin
        xyz="0 0 0"
        rpy="1.5708 0 0" />
      <geometry>
        <cylinder length=".1366" radius=".14879"/>
      </geometry>
    </collision>
  </link>

  <joint
    name="left_front_wheel_joint"
    type="continuous">
    <origin
      xyz=".75295 -0.099925 0"
      rpy="0 0 0" />
    <parent
      link="left_rocker_link" />
    <child
      link="left_front_wheel_link" />
    <axis
      xyz="0 1 0" />
  </joint>

  <link
    name="right_front_wheel_link">
    <inertial>
      <origin
        xyz="0 0 0"
        rpy="0 0 0" />
      <mass
        value="5.28366197630003" />
      <inertia
        ixx="0"
        ixy="0"
        ixz="0"
        iyy="0"
        iyz="0"
        izz="0" />
    </inertial>
    <visual>
      <origin
        xyz="0 0 0"
        rpy="1.5708 0 0" />
      <geometry>
        <cylinder length=".1366" radius=".14879"/>
      </geometry>

    </visual>
    <collision>
      <origin
        xyz="0 0 0"
        rpy="1.5708 0 0" />
      <geometry>
        <cylinder length=".1366" radius=".14879"/>
      </geometry>
    </collision>
  </link>

  <joint
    name="right_front_wheel_joint"
    type="continuous">
    <origin
      xyz=".75295 0.099925 0"
      rpy="0 0 0" />
    <parent
      link="right_rocker_link" />
    <child
      link="right_front_wheel_link" />
    <axis
      xyz="0 1 0" />
  </joint>

  <link
    name="left_bogie_link">
    <inertial>
      <origin
        xyz="-1.85962356624714E-15 -0.0509936533690532 -0.00317500000001342"
        rpy="0 0 0" />
      <mass
        value="0.132129874228365" />
      <inertia
        ixx="0"
        ixy="0"
        ixz="0"
        iyy="0"
        iyz="0"
        izz="0" />
    </inertial>
    <visual>
      <origin
        xyz=".130825 0 0"
        rpy="0 0 0" />
      <geometry>
        <box size = ".290 .00635 .05876" />
      </geometry>
    </visual>
    <collision>
      <origin
        xyz="0 0 0"
        rpy="0 0 0" />
      <geometry>
        <box size = ".290 .00635 .05876" />
      </geometry>
    </collision>
    <visual>
      <origin
        xyz="-0.08408305 0 -0.10020627"
        rpy="0 -0.87266 0" />
      <geometry>
        <box size = ".290 .00635 .05876" />
      </geometry>
    </visual>
    <collision>
      <origin
        xyz="-0.08408305 0 -0.10020627"
        rpy="0 -0.87266 0" />
      <geometry>
        <box size = ".290 .00635 .05876" />
      </geometry>
    </collision>
  </link>
  <joint
    name="left_bogie_joint"
    type="revolute">
    <origin
      xyz="-0.0316348 -0.00635 -0.249785" 
      rpy="0 0 0" /> 
    <parent
      link="left_rocker_link" />
    <child
      link="left_bogie_link" />
    <axis
      xyz="0 1 0" />
    <limit
      lower="-3.142"
      upper="3.142"
      effort="0"
      velocity="0" />
  </joint>

  <link
    name="right_bogie_link">
    <inertial>
      <origin
        xyz="-1.85962356624714E-15 -0.0509936533690532 -0.00317500000001342"
        rpy="0 0 0" />
      <mass
        value="0.132129874228365" />
      <inertia
        ixx="0"
        ixy="0"
        ixz="0"
        iyy="0"
        iyz="0"
        izz="0" />
    </inertial>
    <visual>
      <origin
        xyz=".130825 0 0"
        rpy="0 0 0" />
      <geometry>
        <box size = ".290 .00635 .05876" />
      </geometry>
    </visual>
    <collision>
      <origin
        xyz="0 0 0"
        rpy="0 0 0" />
      <geometry>
        <box size = ".290 .00635 .05876" />
      </geometry>
    </collision>
    <visual>
      <origin
        xyz="-0.08408305 0 -0.10020627"
        rpy="0 -0.87266 0" />
      <geometry>
        <box size = ".290 .00635 .05876" />
      </geometry>
    </visual>
    <collision>
      <origin
        xyz="-0.08408305 0 -0.10020627"
        rpy="0 -0.87266 0" />
      <geometry>
        <box size = ".290 .00635 .05876" />
      </geometry>
    </collision>
  </link>
  <joint
    name="right_bogie_joint"
    type="revolute">
    <origin
      xyz="-0.0316348 0.00635 -0.249785" 
      rpy="0 0 0" /> 
    <parent
      link="right_rocker_link" />
    <child
      link="right_bogie_link" />
    <axis
      xyz="0 1 0" />
    <limit
      lower="-3.142"
      upper="3.142"
      effort="0"
      velocity="0" />
  </joint>

  <link
    name="right_middle_wheel_link">
    <inertial>
      <origin
        xyz="0 0 0"
        rpy="0 0 0" />
      <mass
        value="5.28366197630003" />
      <inertia
        ixx="0"
        ixy="0"
        ixz="0"
        iyy="0"
        iyz="0"
        izz="0" />
    </inertial>
    <visual>
      <origin
        xyz="0 0 0"
        rpy="1.5708 0 0" />
      <geometry>
        <cylinder length=".1366" radius=".14879"/>
      </geometry>

    </visual>
    <collision>
      <origin
        xyz="0 0 0"
        rpy="1.5708 0 0" />
      <geometry>
        <cylinder length=".1366" radius=".14879"/>
      </geometry>
    </collision>
  </link>

  <joint
    name="right_middle_wheel_joint"
    type="continuous">
    <origin
      xyz=".26165 0.099925 0"
      rpy="0 0 0" />
    <parent
      link="right_bogie_link" />
    <child
      link="right_middle_wheel_link" />
    <axis
      xyz="0 1 0" />
  </joint>

  <link
    name="right_rear_wheel_link">
    <inertial>
      <origin
        xyz="0 0 0"
        rpy="0 0 0" />
      <mass
        value="5.28366197630003" />
      <inertia
        ixx="0"
        ixy="0"
        ixz="0"
        iyy="0"
        iyz="0"
        izz="0" />
    </inertial>
    <visual>
      <origin
        xyz="0 0 0"
        rpy="1.5708 0 0" />
      <geometry>
        <cylinder length=".1366" radius=".14879"/>
      </geometry>

    </visual>
    <collision>
      <origin
        xyz="0 0 0"
        rpy="1.5708 0 0" />
      <geometry>
        <cylinder length=".1366" radius=".14879"/>
      </geometry>
    </collision>
  </link>

  <joint
    name="right_rear_wheel_joint"
    type="continuous">
    <origin
      xyz="-0.16817 0.099925 -0.20041"
      rpy="0 0 0" />
    <parent
      link="right_bogie_link" />
    <child
      link="right_rear_wheel_link" />
    <axis
      xyz="0 1 0" />
  </joint>

  <link
    name="left_middle_wheel_link">
    <inertial>
      <origin
        xyz="0 0 0"
        rpy="0 0 0" />
      <mass
        value="5.28366197630003" />
      <inertia
        ixx="0"
        ixy="0"
        ixz="0"
        iyy="0"
        iyz="0"
        izz="0" />
    </inertial>
    <visual>
      <origin
        xyz="0 0 0"
        rpy="1.5708 0 0" />
      <geometry>
        <cylinder length=".1366" radius=".14879"/>
      </geometry>

    </visual>
    <collision>
      <origin
        xyz="0 0 0"
        rpy="1.5708 0 0" />
      <geometry>
        <cylinder length=".1366" radius=".14879"/>
      </geometry>
    </collision>
  </link>

  <joint
    name="left_middle_wheel_joint"
    type="continuous">
    <origin
      xyz=".26165 -0.099925 0"
      rpy="0 0 0" />
    <parent
      link="left_bogie_link" />
    <child
      link="left_middle_wheel_link" />
    <axis
      xyz="0 1 0" />
  </joint>

  <link
    name="left_rear_wheel_link">
    <inertial>
      <origin
        xyz="0 0 0"
        rpy="0 0 0" />
      <mass
        value="5.28366197630003" />
      <inertia
        ixx="0"
        ixy="0"
        ixz="0"
        iyy="0"
        iyz="0"
        izz="0" />
    </inertial>
    <visual>
      <origin
        xyz="0 0 0"
        rpy="1.5708 0 0" />
      <geometry>
        <cylinder length=".1366" radius=".14879"/>
      </geometry>

    </visual>
    <collision>
      <origin
        xyz="0 0 0"
        rpy="1.5708 0 0" />
      <geometry>
        <cylinder length=".1366" radius=".14879"/>
      </geometry>
    </collision>
  </link>

  <joint
    name="left_rear_wheel_joint"
    type="continuous">
    <origin
      xyz="-0.16817 -0.099925 -0.20041"
      rpy="0 0 0" />
    <parent
      link="left_bogie_link" />
    <child
      link="left_rear_wheel_link" />
    <axis
      xyz="0 1 0" />
  </joint>
</robot>
