<robot
  name="assy">
  <link
    name="base_link">
    <inertial>
      <origin
        xyz="9.60927531771405E-18 0 0"
        rpy="0 0 0" />
      <mass
        value="6.35" />
      <inertia
        ixx="0"
        ixy="0"
        ixz="0"
        iyy="0"
        iyz="0"
        izz="0" />
    </inertial>
    <visual>
      <origin
        xyz="0 0 0"
        rpy="0 0 0" />
      <geometry>
        <mesh
          filename="package://assy/meshes/base_link.STL" />
      </geometry>
      <material
        name="">
        <color
          rgba="0.792156862745098 0.819607843137255 0.933333333333333 1" />
      </material>
    </visual>
    <collision>
      <origin
        xyz="0 0 0"
        rpy="0 0 0" />
      <geometry>
        <mesh
          filename="package://assy/meshes/base_link.STL" />
      </geometry>
    </collision>
  </link>
  <link
    name="L1">
    <inertial>
      <origin
        xyz="0.025 0 0"
        rpy="0 0 0" />
      <mass
        value="0.3927" />
      <inertia
        ixx="0"
        ixy="0"
        ixz="0"
        iyy="0"
        iyz="0"
        izz="0" />
    </inertial>
    <visual>
      <origin
        xyz="0 0 0"
        rpy="0 0 0" />
      <geometry>
        <mesh
          filename="package://assy/meshes/L1.STL" />
      </geometry>
      <material
        name="">
        <color
          rgba="0.75294 0.75294 0.75294 1" />
      </material>
    </visual>
    <collision>
      <origin
        xyz="0 0 0"
        rpy="0 0 0" />
      <geometry>
        <mesh
          filename="package://assy/meshes/L1.STL" />
      </geometry>
    </collision>
  </link>
  <joint
    name="J1"
    type="continuous">
    <origin
      xyz="-0.15 0.075 -0.0635"
      rpy="0 0 0" />
    <parent
      link="base_link" />
    <child
      link="L1" />
    <axis
      xyz="1 0 0" />
  </joint>
  <link
    name="L2">
    <inertial>
      <origin
        xyz="0.025 0 0"
        rpy="0 0 0" />
      <mass
        value="0.392699081698724" />
      <inertia
        ixx="0"
        ixy="0"
        ixz="0"
        iyy="0"
        iyz="0"
        izz="0" />
    </inertial>
    <visual>
      <origin
        xyz="0 0 0"
        rpy="0 0 0" />
      <geometry>
        <mesh
          filename="package://assy/meshes/L2.STL" />
      </geometry>
      <material
        name="">
        <color
          rgba="0.752941176470588 0.752941176470588 0.752941176470588 1" />
      </material>
    </visual>
    <collision>
      <origin
        xyz="0 0 0"
        rpy="0 0 0" />
      <geometry>
        <mesh
          filename="package://assy/meshes/L2.STL" />
      </geometry>
    </collision>
  </link>
  <joint
    name="J2"
    type="continuous">
    <origin
      xyz="-0.15 -0.075 -0.0635"
      rpy="0 0 0" />
    <parent
      link="base_link" />
    <child
      link="L2" />
    <axis
      xyz="1 0 0" />
  </joint>
  <link
    name="L3">
    <inertial>
      <origin
        xyz="-0.025 0 0"
        rpy="0 0 0" />
      <mass
        value="0.3927" />
      <inertia
        ixx="0"
        ixy="0"
        ixz="0"
        iyy="0"
        iyz="0"
        izz="0" />
    </inertial>
    <visual>
      <origin
        xyz="0 0 0"
        rpy="0 0 0" />
      <geometry>
        <mesh
          filename="package://assy/meshes/L3.STL" />
      </geometry>
      <material
        name="">
        <color
          rgba="0.75294 0.75294 0.75294 1" />
      </material>
    </visual>
    <collision>
      <origin
        xyz="0 0 0"
        rpy="0 0 0" />
      <geometry>
        <mesh
          filename="package://assy/meshes/L3.STL" />
      </geometry>
    </collision>
  </link>
  <joint
    name="J3"
    type="continuous">
    <origin
      xyz="0.15 0.075 -0.0635"
      rpy="0 0 0" />
    <parent
      link="base_link" />
    <child
      link="L3" />
    <axis
      xyz="1 0 0" />
  </joint>
  <link
    name="L4">
    <inertial>
      <origin
        xyz="-0.025 0 0"
        rpy="0 0 0" />
      <mass
        value="0.3927" />
      <inertia
        ixx="0"
        ixy="0"
        ixz="0"
        iyy="0"
        iyz="0"
        izz="0" />
    </inertial>
    <visual>
      <origin
        xyz="0 0 0"
        rpy="0 0 0" />
      <geometry>
        <mesh
          filename="package://assy/meshes/L4.STL" />
      </geometry>
      <material
        name="">
        <color
          rgba="0.75294 0.75294 0.75294 1" />
      </material>
    </visual>
    <collision>
      <origin
        xyz="0 0 0"
        rpy="0 0 0" />
      <geometry>
        <mesh
          filename="package://assy/meshes/L4.STL" />
      </geometry>
    </collision>
  </link>
  <joint
    name="J4"
    type="continuous">
    <origin
      xyz="0.15 -0.075 -0.0635"
      rpy="0 0 0" />
    <parent
      link="base_link" />
    <child
      link="L4" />
    <axis
      xyz="1 0 0" />
  </joint>
</robot>